Traceback (most recent call last):
  File "/home/lw/.local/lib/python3.11/site-packages/nbclient/client.py", line 778, in _async_poll_for_reply
    msg = await ensure_async(self.kc.shell_channel.get_msg(timeout=new_timeout))
          ^^^^^^^^^^^^^^^^^^^^^^^^^^^^^^^^^^^^^^^^^^^^^^^^^^^^^^^^^^^^^^^^^^^^^^
  File "/home/lw/.local/lib/python3.11/site-packages/jupyter_core/utils/__init__.py", line 189, in ensure_async
    result = await obj
             ^^^^^^^^^
  File "/home/lw/.local/lib/python3.11/site-packages/jupyter_client/channels.py", line 315, in get_msg
    raise Empty
_queue.Empty

During handling of the above exception, another exception occurred:

Traceback (most recent call last):
  File "/home/lw/.local/lib/python3.11/site-packages/jupyter_cache/executors/utils.py", line 58, in single_nb_execution
    executenb(
  File "/home/lw/.local/lib/python3.11/site-packages/nbclient/client.py", line 1305, in execute
    return NotebookClient(nb=nb, resources=resources, km=km, **kwargs).execute()
           ^^^^^^^^^^^^^^^^^^^^^^^^^^^^^^^^^^^^^^^^^^^^^^^^^^^^^^^^^^^^^^^^^^^^^
  File "/home/lw/.local/lib/python3.11/site-packages/jupyter_core/utils/__init__.py", line 173, in wrapped
    return loop.run_until_complete(inner)
           ^^^^^^^^^^^^^^^^^^^^^^^^^^^^^^
  File "/usr/lib/python3.11/asyncio/base_events.py", line 653, in run_until_complete
    return future.result()
           ^^^^^^^^^^^^^^^
  File "/home/lw/.local/lib/python3.11/site-packages/nbclient/client.py", line 705, in async_execute
    await self.async_execute_cell(
  File "/home/lw/.local/lib/python3.11/site-packages/nbclient/client.py", line 1001, in async_execute_cell
    exec_reply = await self.task_poll_for_reply
                 ^^^^^^^^^^^^^^^^^^^^^^^^^^^^^^
  File "/home/lw/.local/lib/python3.11/site-packages/nbclient/client.py", line 802, in _async_poll_for_reply
    error_on_timeout_execute_reply = await self._async_handle_timeout(timeout, cell)
                                     ^^^^^^^^^^^^^^^^^^^^^^^^^^^^^^^^^^^^^^^^^^^^^^^
  File "/home/lw/.local/lib/python3.11/site-packages/nbclient/client.py", line 852, in _async_handle_timeout
    raise CellTimeoutError.error_from_timeout_and_cell(
nbclient.exceptions.CellTimeoutError: A cell timed out while it was being executed, after 100 seconds.
The message was: Cell execution timed out.
Here is a preview of the cell contents:
-------------------
u0 = GridFunction(fesH1)
pre = BilinearForm(uH1*vH1*ds).Assemble().mat.Inverse(freedofs=fesH1.FreeDofs()) 
with TaskManager(): # pajetrace=1000*1000*1000):
    D = HypersingularOperator(fesH1, intorder=12, leafsize=40, eta=3., eps=1e-4, method="aca", testhmatrix=False)
    
    M = BilinearForm( v.Trace() * uH1 * ds(bonus_intorder=3)).Assemble()
    Kt = DoubleLayerPotentialOperator(fesL2, fesH1, intorder=12, leafsize=40, eta=3., eps=1e-4, method="aca")    
    rhs = ( (0.5 * M.mat.T - Kt.mat) * u1.vec ).Evaluate()

    CG(mat=D.mat+S, pre=pre, rhs=rhs, sol=u0.vec, tol=1e-8, maxsteps=200, initialize=False, printrates=True)
-------------------

